Workbook

Sheet Executive Report
A1: JANVI AIKA - EXECUTIVE ORDER ANALYSIS REPORT: COD vs. PARTIAL COD vs. PREPAID ORDERS
A3: Comprehensive Performance Evaluation, Delivery Realization, RTO Risk Assessment & Strategic Action Plan
A5: 1. EXECUTIVE KPI SUMMARY
A6: TOTAL ORDERS | C6: TOTAL GROSS REVENUE | E6: NET DELIVERED REVENUE | G6: DELIVERY SUCCESS RATE | I6: COD RTO REVENUE LOSS | K6: COD FAILURE RATE
A7: =COUNT(Master_Orders!A2:A174) | C7: =SUM(Master_Orders!E2:E174) | E7: =SUMIF(Master_Orders!K2:K174, "Delivered", Master_Orders!E2:E174) | G7: =COUNTIF(Master_Orders!K2:K174, "Delivered")/COUNT(Master_Orders!A2:A174) | I7: =SUMIFS(Master_Orders!E2:E174, Master_Orders!J2:J174, "COD", Master_Orders!K2:K174, "RTO / Returned") | K7: =(COUNTIFS(Master_Orders!J2:J174, "COD", Master_Orders!K2:K174, "RTO / Returned") + COUNTIFS(Master_Orders!J2:J174, "COD", Master_Orders!K2:K174, "Canceled")) / COUNTIF(Master_Orders!J2:J174, "COD")
A9: 2. PAYMENT CATEGORY COMPARATIVE REALIZATION MATRIX
A10: Payment Category | B10: Total Orders | C10: Order Share % | D10: Gross Revenue (Rs.) | E10: Revenue Share % | F10: AOV (Rs.) | G10: Delivered Count | H10: Delivered Net Rev (Rs.) | I10: RTO Count | J10: RTO Rate % | K10: RTO Rev at Risk (Rs.) | L10: Canceled Count | M10: Overall Failure Rate %
A11: Cash on Delivery (COD) | B11: =COUNTIF(Master_Orders!J2:J174, "COD") | C11: =B11/B14 | D11: =SUMIF(Master_Orders!J2:J174, "COD", Master_Orders!E2:E174) | E11: =D11/D14 | F11: =D11/B11 | G11: =COUNTIFS(Master_Orders!J2:J174, "COD", Master_Orders!K2:K174, "Delivered") | H11: =SUMIFS(Master_Orders!E2:E174, Master_Orders!J2:J174, "COD", Master_Orders!K2:K174, "Delivered") | I11: =COUNTIFS(Master_Orders!J2:J174, "COD", Master_Orders!K2:K174, "RTO / Returned") | J11: =I11/B11 | K11: =SUMIFS(Master_Orders!E2:E174, Master_Orders!J2:J174, "COD", Master_Orders!K2:K174, "RTO / Returned") | L11: =COUNTIFS(Master_Orders!J2:J174, "COD", Master_Orders!K2:K174, "Canceled") | M11: =(I11+L11)/B11
A12: Partial COD | B12: =COUNTIF(Master_Orders!J2:J174, "Partial COD") | C12: =B12/B14 | D12: =SUMIF(Master_Orders!J2:J174, "Partial COD", Master_Orders!E2:E174) | E12: =D12/D14 | F12: =D12/B12 | G12: =COUNTIFS(Master_Orders!J2:J174, "Partial COD", Master_Orders!K2:K174, "Delivered") | H12: =SUMIFS(Master_Orders!E2:E174, Master_Orders!J2:J174, "Partial COD", Master_Orders!K2:K174, "Delivered") | I12: =COUNTIFS(Master_Orders!J2:J174, "Partial COD", Master_Orders!K2:K174, "RTO / Returned") | J12: =I12/B12 | K12: =SUMIFS(Master_Orders!E2:E174, Master_Orders!J2:J174, "Partial COD", Master_Orders!K2:K174, "RTO / Returned") | L12: =COUNTIFS(Master_Orders!J2:J174, "Partial COD", Master_Orders!K2:K174, "Canceled") | M12: =(I12+L12)/B12
A13: Prepaid (Razorpay / UPI / Cards) | B13: =COUNTIF(Master_Orders!J2:J174, "Prepaid") | C13: =B13/B14 | D13: =SUMIF(Master_Orders!J2:J174, "Prepaid", Master_Orders!E2:E174) | E13: =D13/D14 | F13: =D13/B13 | G13: =COUNTIFS(Master_Orders!J2:J174, "Prepaid", Master_Orders!K2:K174, "Delivered") | H13: =SUMIFS(Master_Orders!E2:E174, Master_Orders!J2:J174, "Prepaid", Master_Orders!K2:K174, "Delivered") | I13: =COUNTIFS(Master_Orders!J2:J174, "Prepaid", Master_Orders!K2:K174, "RTO / Returned") | J13: =I13/B13 | K13: =SUMIFS(Master_Orders!E2:E174, Master_Orders!J2:J174, "Prepaid", Master_Orders!K2:K174, "RTO / Returned") | L13: =COUNTIFS(Master_Orders!J2:J174, "Prepaid", Master_Orders!K2:K174, "Canceled") | M13: =(I13+L13)/B13
A14: Total Portfolio / Combined | B14: =SUM(B11:B13) | C14: =SUM(C11:C13) | D14: =SUM(D11:D13) | E14: =SUM(E11:E13) | F14: =D14/B14 | G14: =SUM(G11:G13) | H14: =SUM(H11:H13) | I14: =SUM(I11:I13) | J14: =I14/B14 | K14: =SUM(K11:K13) | L14: =SUM(L11:L13) | M14: =(I14+L14)/B14
A16: 3. GEOGRAPHIC DISTRIBUTION & TOP DEMAND REGIONS
A17: Payment Category | B17: Top State #1 | C17: Top State #2 | D17: Top State #3 | E17: Top State #4 | F17: Demand Concentration
A18: Prepaid | B18: Tamil Nadu (58 orders) | C18: Andhra Pradesh (15 orders) | D18: Telangana (13 orders) | E18: Karnataka (11 orders) | F18: High concentration in South Metro & Tier-1 cities
A19: Cash on Delivery (COD) | B19: Tamil Nadu (30 orders) | C19: Telangana (8 orders) | D19: Karnataka (6 orders) | E19: Andhra Pradesh (4 orders) | F19: Tier-2/3 pincodes in TN and TS show high RTO rates
A20: Partial COD | B20: Telangana (4 orders) | C20: Tamil Nadu (3 orders) | D20: Maharashtra (3 orders) | E20: Kerala (1 order) | F20: Strong acceptance in urban hubs looking for intent verification
A22: 4. STRATEGIC RECOMMENDATIONS & ACTION PLAN
A23: Pillar / Focus Area | B23: Current Issue / Risk | C23: Proposed Action / Strategic Policy | D23: Expected Impact & Result
A24: Mandatory Partial COD | B24: Pure COD incurs 25% RTO rate and Rs. 18.5k in locked inventory | C24: Enforce Rs. 150-Rs. 200 non-refundable advance deposit for all COD checkouts | D24: Eliminates non-serious orders; reduces RTO to < 2% (matching Partial COD 0% RTO)
A25: Prepaid Discount Incentives | B25: 30% of buyers select COD due to lack of immediate checkout incentive | C25: Offer 5% instant discount or free gift for UPI / Razorpay checkout | D25: Shifts ~40% of prospective COD orders to Prepaid, locking in instant cashflow
A26: Automated NDR Verification | B26: Doorstep refusal due to buyer absence or impulse cancellation | C26: Implement automated WhatsApp order verification prior to Shiprocket manifest | D26: Prevents dispatch of unconfirmed orders; saves forward and return freight costs
A27: Regional Fulfillment Hubs | B27: 80%+ demand is concentrated in South India (TN, TS, AP, KA) | C27: Optimize courier routing via South India express hubs for <48h delivery | D27: Faster transit times directly improve delivery acceptance rate and reduce buyer remorse

Sheet Side_By_Side_Comparison
A1: JANVI AIKA - SIDE-BY-SIDE DAY-WISE COMPARATIVE ANALYSIS: COD vs. PARTIAL COD vs. PREPAID
A3: Order Date | B3: ORDER VOLUME MIX | E3: GROSS REVENUE (Rs.) | H3: DELIVERED ORDERS | K3: RTO / RETURNED ORDERS | N3: Total Daily Rev
B4: COD | C4: Partial COD | D4: Prepaid | E4: COD | F4: Partial COD | G4: Prepaid | H4: COD | I4: Partial COD | J4: Prepaid | K4: COD | L4: Partial COD | M4: Prepaid
A5: 2026-06-22 | B5: =COUNTIFS(Master_Orders!D2:D174, "2026-06-22", Master_Orders!J2:J174, "COD") | C5: =COUNTIFS(Master_Orders!D2:D174, "2026-06-22", Master_Orders!J2:J174, "Partial COD") | D5: =COUNTIFS(Master_Orders!D2:D174, "2026-06-22", Master_Orders!J2:J174, "Prepaid") | E5: =SUMIFS(Master_Orders!E2:E174, Master_Orders!D2:D174, "2026-06-22", Master_Orders!J2:J174, "COD") | F5: =SUMIFS(Master_Orders!E2:E174, Master_Orders!D2:D174, "2026-06-22", Master_Orders!J2:J174, "Partial COD") | G5: =SUMIFS(Master_Orders!E2:E174, Master_Orders!D2:D174, "2026-06-22", Master_Orders!J2:J174, "Prepaid") | H5: =COUNTIFS(Master_Orders!D2:D174, "2026-06-22", Master_Orders!J2:J174, "COD", Master_Orders!K2:K174, "Delivered") | I5: =COUNTIFS(Master_Orders!D2:D174, "2026-06-22", Master_Orders!J2:J174, "Partial COD", Master_Orders!K2:K174, "Delivered") | J5: =COUNTIFS(Master_Orders!D2:D174, "2026-06-22", Master_Orders!J2:J174, "Prepaid", Master_Orders!K2:K174, "Delivered") | K5: =COUNTIFS(Master_Orders!D2:D174, "2026-06-22", Master_Orders!J2:J174, "COD", Master_Orders!K2:K174, "RTO / Returned") | L5: =COUNTIFS(Master_Orders!D2:D174, "2026-06-22", Master_Orders!J2:J174, "Partial COD", Master_Orders!K2:K174, "RTO / Returned") | M5: =COUNTIFS(Master_Orders!D2:D174, "2026-06-22", Master_Orders!J2:J174, "Prepaid", Master_Orders!K2:K174, "RTO / Returned") | N5: =E5+F5+G5
A6: 2026-06-24 | B6: =COUNTIFS(Master_Orders!D2:D174, "2026-06-24", Master_Orders!J2:J174, "COD") | C6: =COUNTIFS(Master_Orders!D2:D174, "2026-06-24", Master_Orders!J2:J174, "Partial COD") | D6: =COUNTIFS(Master_Orders!D2:D174, "2026-06-24", Master_Orders!J2:J174, "Prepaid") | E6: =SUMIFS(Master_Orders!E2:E174, Master_Orders!D2:D174, "2026-06-24", Master_Orders!J2:J174, "COD") | F6: =SUMIFS(Master_Orders!E2:E174, Master_Orders!D2:D174, "2026-06-24", Master_Orders!J2:J174, "Partial COD") | G6: =SUMIFS(Master_Orders!E2:E174, Master_Orders!D2:D174, "2026-06-24", Master_Orders!J2:J174, "Prepaid") | H6: =COUNTIFS(Master_Orders!D2:D174, "2026-06-24", Master_Orders!J2:J174, "COD", Master_Orders!K2:K174, "Delivered") | I6: =COUNTIFS(Master_Orders!D2:D174, "2026-06-24", Master_Orders!J2:J174, "Partial COD", Master_Orders!K2:K174, "Delivered") | J6: =COUNTIFS(Master_Orders!D2:D174, "2026-06-24", Master_Orders!J2:J174, "Prepaid", Master_Orders!K2:K174, "Delivered") | K6: =COUNTIFS(Master_Orders!D2:D174, "2026-06-24", Master_Orders!J2:J174, "COD", Master_Orders!K2:K174, "RTO / Returned") | L6: =COUNTIFS(Master_Orders!D2:D174, "2026-06-24", Master_Orders!J2:J174, "Partial COD", Master_Orders!K2:K174, "RTO / Returned") | M6: =COUNTIFS(Master_Orders!D2:D174, "2026-06-24", Master_Orders!J2:J174, "Prepaid", Master_Orders!K2:K174, "RTO / Returned") | N6: =E6+F6+G6
A7: 2026-06-25 | B7: =COUNTIFS(Master_Orders!D2:D174, "2026-06-25", Master_Orders!J2:J174, "COD") | C7: =COUNTIFS(Master_Orders!D2:D174, "2026-06-25", Master_Orders!J2:J174, "Partial COD") | D7: =COUNTIFS(Master_Orders!D2:D174, "2026-06-25", Master_Orders!J2:J174, "Prepaid") | E7: =SUMIFS(Master_Orders!E2:E174, Master_Orders!D2:D174, "2026-06-25", Master_Orders!J2:J174, "COD") | F7: =SUMIFS(Master_Orders!E2:E174, Master_Orders!D2:D174, "2026-06-25", Master_Orders!J2:J174, "Partial COD") | G7: =SUMIFS(Master_Orders!E2:E174, Master_Orders!D2:D174, "2026-06-25", Master_Orders!J2:J174, "Prepaid") | H7: =COUNTIFS(Master_Orders!D2:D174, "2026-06-25", Master_Orders!J2:J174, "COD", Master_Orders!K2:K174, "Delivered") | I7: =COUNTIFS(Master_Orders!D2:D174, "2026-06-25", Master_Orders!J2:J174, "Partial COD", Master_Orders!K2:K174, "Delivered") | J7: =COUNTIFS(Master_Orders!D2:D174, "2026-06-25", Master_Orders!J2:J174, "Prepaid", Master_Orders!K2:K174, "Delivered") | K7: =COUNTIFS(Master_Orders!D2:D174, "2026-06-25", Master_Orders!J2:J174, "COD", Master_Orders!K2:K174, "RTO / Returned") | L7: =COUNTIFS(Master_Orders!D2:D174, "2026-06-25", Master_Orders!J2:J174, "Partial COD", Master_Orders!K2:K174, "RTO / Returned") | M7: =COUNTIFS(Master_Orders!D2:D174, "2026-06-25", Master_Orders!J2:J174, "Prepaid", Master_Orders!K2:K174, "RTO / Returned") | N7: =E7+F7+G7
A8: 2026-06-27 | B8: =COUNTIFS(Master_Orders!D2:D174, "2026-06-27", Master_Orders!J2:J174, "COD") | C8: =COUNTIFS(Master_Orders!D2:D174, "2026-06-27", Master_Orders!J2:J174, "Partial COD") | D8: =COUNTIFS(Master_Orders!D2:D174, "2026-06-27", Master_Orders!J2:J174, "Prepaid") | E8: =SUMIFS(Master_Orders!E2:E174, Master_Orders!D2:D174, "2026-06-27", Master_Orders!J2:J174, "COD") | F8: =SUMIFS(Master_Orders!E2:E174, Master_Orders!D2:D174, "2026-06-27", Master_Orders!J2:J174, "Partial COD") | G8: =SUMIFS(Master_Orders!E2:E174, Master_Orders!D2:D174, "2026-06-27", Master_Orders!J2:J174, "Prepaid") | H8: =COUNTIFS(Master_Orders!D2:D174, "2026-06-27", Master_Orders!J2:J174, "COD", Master_Orders!K2:K174, "Delivered") | I8: =COUNTIFS(Master_Orders!D2:D174, "2026-06-27", Master_Orders!J2:J174, "Partial COD", Master_Orders!K2:K174, "Delivered") | J8: =COUNTIFS(Master_Orders!D2:D174, "2026-06-27", Master_Orders!J2:J174, "Prepaid", Master_Orders!K2:K174, "Delivered") | K8: =COUNTIFS(Master_Orders!D2:D174, "2026-06-27", Master_Orders!J2:J174, "COD", Master_Orders!K2:K174, "RTO / Returned") | L8: =COUNTIFS(Master_Orders!D2:D174, "2026-06-27", Master_Orders!J2:J174, "Partial COD", Master_Orders!K2:K174, "RTO / Returned") | M8: =COUNTIFS(Master_Orders!D2:D174, "2026-06-27", Master_Orders!J2:J174, "Prepaid", Master_Orders!K2:K174, "RTO / Returned") | N8: =E8+F8+G8
A9: 2026-06-28 | B9: =COUNTIFS(Master_Orders!D2:D174, "2026-06-28", Master_Orders!J2:J174, "COD") | C9: =COUNTIFS(Master_Orders!D2:D174, "2026-06-28", Master_Orders!J2:J174, "Partial COD") | D9: =COUNTIFS(Master_Orders!D2:D174, "2026-06-28", Master_Orders!J2:J174, "Prepaid") | E9: =SUMIFS(Master_Orders!E2:E174, Master_Orders!D2:D174, "2026-06-28", Master_Orders!J2:J174, "COD") | F9: =SUMIFS(Master_Orders!E2:E174, Master_Orders!D2:D174, "2026-06-28", Master_Orders!J2:J174, "Partial COD") | G9: =SUMIFS(Master_Orders!E2:E174, Master_Orders!D2:D174, "2026-06-28", Master_Orders!J2:J174, "Prepaid") | H9: =COUNTIFS(Master_Orders!D2:D174, "2026-06-28", Master_Orders!J2:J174, "COD", Master_Orders!K2:K174, "Delivered") | I9: =COUNTIFS(Master_Orders!D2:D174, "2026-06-28", Master_Orders!J2:J174, "Partial COD", Master_Orders!K2:K174, "Delivered") | J9: =COUNTIFS(Master_Orders!D2:D174, "2026-06-28", Master_Orders!J2:J174, "Prepaid", Master_Orders!K2:K174, "Delivered") | K9: =COUNTIFS(Master_Orders!D2:D174, "2026-06-28", Master_Orders!J2:J174, "COD", Master_Orders!K2:K174, "RTO / Returned") | L9: =COUNTIFS(Master_Orders!D2:D174, "2026-06-28", Master_Orders!J2:J174, "Partial COD", Master_Orders!K2:K174, "RTO / Returned") | M9: =COUNTIFS(Master_Orders!D2:D174, "2026-06-28", Master_Orders!J2:J174, "Prepaid", Master_Orders!K2:K174, "RTO / Returned") | N9: =E9+F9+G9
A10: 2026-06-29 | B10: =COUNTIFS(Master_Orders!D2:D174, "2026-06-29", Master_Orders!J2:J174, "COD") | C10: =COUNTIFS(Master_Orders!D2:D174, "2026-06-29", Master_Orders!J2:J174, "Partial COD") | D10: =COUNTIFS(Master_Orders!D2:D174, "2026-06-29", Master_Orders!J2:J174, "Prepaid") | E10: =SUMIFS(Master_Orders!E2:E174, Master_Orders!D2:D174, "2026-06-29", Master_Orders!J2:J174, "COD") | F10: =SUMIFS(Master_Orders!E2:E174, Master_Orders!D2:D174, "2026-06-29", Master_Orders!J2:J174, "Partial COD") | G10: =SUMIFS(Master_Orders!E2:E174, Master_Orders!D2:D174, "2026-06-29", Master_Orders!J2:J174, "Prepaid") | H10: =COUNTIFS(Master_Orders!D2:D174, "2026-06-29", Master_Orders!J2:J174, "COD", Master_Orders!K2:K174, "Delivered") | I10: =COUNTIFS(Master_Orders!D2:D174, "2026-06-29", Master_Orders!J2:J174, "Partial COD", Master_Orders!K2:K174, "Delivered") | J10: =COUNTIFS(Master_Orders!D2:D174, "2026-06-29", Master_Orders!J2:J174, "Prepaid", Master_Orders!K2:K174, "Delivered") | K10: =COUNTIFS(Master_Orders!D2:D174, "2026-06-29", Master_Orders!J2:J174, "COD", Master_Orders!K2:K174, "RTO / Returned") | L10: =COUNTIFS(Master_Orders!D2:D174, "2026-06-29", Master_Orders!J2:J174, "Partial COD", Master_Orders!K2:K174, "RTO / Returned") | M10: =COUNTIFS(Master_Orders!D2:D174, "2026-06-29", Master_Orders!J2:J174, "Prepaid", Master_Orders!K2:K174, "RTO / Returned") | N10: =E10+F10+G10
A11: 2026-06-30 | B11: =COUNTIFS(Master_Orders!D2:D174, "2026-06-30", Master_Orders!J2:J174, "COD") | C11: =COUNTIFS(Master_Orders!D2:D174, "2026-06-30", Master_Orders!J2:J174, "Partial COD") | D11: =COUNTIFS(Master_Orders!D2:D174, "2026-06-30", Master_Orders!J2:J174, "Prepaid") | E11: =SUMIFS(Master_Orders!E2:E174, Master_Orders!D2:D174, "2026-06-30", Master_Orders!J2:J174, "COD") | F11: =SUMIFS(Master_Orders!E2:E174, Master_Orders!D2:D174, "2026-06-30", Master_Orders!J2:J174, "Partial COD") | G11: =SUMIFS(Master_Orders!E2:E174, Master_Orders!D2:D174, "2026-06-30", Master_Orders!J2:J174, "Prepaid") | H11: =COUNTIFS(Master_Orders!D2:D174, "2026-06-30", Master_Orders!J2:J174, "COD", Master_Orders!K2:K174, "Delivered") | I11: =COUNTIFS(Master_Orders!D2:D174, "2026-06-30", Master_Orders!J2:J174, "Partial COD", Master_Orders!K2:K174, "Delivered") | J11: =COUNTIFS(Master_Orders!D2:D174, "2026-06-30", Master_Orders!J2:J174, "Prepaid", Master_Orders!K2:K174, "Delivered") | K11: =COUNTIFS(Master_Orders!D2:D174, "2026-06-30", Master_Orders!J2:J174, "COD", Master_Orders!K2:K174, "RTO / Returned") | L11: =COUNTIFS(Master_Orders!D2:D174, "2026-06-30", Master_Orders!J2:J174, "Partial COD", Master_Orders!K2:K174, "RTO / Returned") | M11: =COUNTIFS(Master_Orders!D2:D174, "2026-06-30", Master_Orders!J2:J174, "Prepaid", Master_Orders!K2:K174, "RTO / Returned") | N11: =E11+F11+G11
A12: 2026-07-01 | B12: =COUNTIFS(Master_Orders!D2:D174, "2026-07-01", Master_Orders!J2:J174, "COD") | C12: =COUNTIFS(Master_Orders!D2:D174, "2026-07-01", Master_Orders!J2:J174, "Partial COD") | D12: =COUNTIFS(Master_Orders!D2:D174, "2026-07-01", Master_Orders!J2:J174, "Prepaid") | E12: =SUMIFS(Master_Orders!E2:E174, Master_Orders!D2:D174, "2026-07-01", Master_Orders!J2:J174, "COD") | F12: =SUMIFS(Master_Orders!E2:E174, Master_Orders!D2:D174, "2026-07-01", Master_Orders!J2:J174, "Partial COD") | G12: =SUMIFS(Master_Orders!E2:E174, Master_Orders!D2:D174, "2026-07-01", Master_Orders!J2:J174, "Prepaid") | H12: =COUNTIFS(Master_Orders!D2:D174, "2026-07-01", Master_Orders!J2:J174, "COD", Master_Orders!K2:K174, "Delivered") | I12: =COUNTIFS(Master_Orders!D2:D174, "2026-07-01", Master_Orders!J2:J174, "Partial COD", Master_Orders!K2:K174, "Delivered") | J12: =COUNTIFS(Master_Orders!D2:D174, "2026-07-01", Master_Orders!J2:J174, "Prepaid", Master_Orders!K2:K174, "Delivered") | K12: =COUNTIFS(Master_Orders!D2:D174, "2026-07-01", Master_Orders!J2:J174, "COD", Master_Orders!K2:K174, "RTO / Returned") | L12: =COUNTIFS(Master_Orders!D2:D174, "2026-07-01", Master_Orders!J2:J174, "Partial COD", Master_Orders!K2:K174, "RTO / Returned") | M12: =COUNTIFS(Master_Orders!D2:D174, "2026-07-01", Master_Orders!J2:J174, "Prepaid", Master_Orders!K2:K174, "RTO / Returned") | N12: =E12+F12+G12
A13: 2026-07-02 | B13: =COUNTIFS(Master_Orders!D2:D174, "2026-07-02", Master_Orders!J2:J174, "COD") | C13: =COUNTIFS(Master_Orders!D2:D174, "2026-07-02", Master_Orders!J2:J174, "Partial COD") | D13: =COUNTIFS(Master_Orders!D2:D174, "2026-07-02", Master_Orders!J2:J174, "Prepaid") | E13: =SUMIFS(Master_Orders!E2:E174, Master_Orders!D2:D174, "2026-07-02", Master_Orders!J2:J174, "COD") | F13: =SUMIFS(Master_Orders!E2:E174, Master_Orders!D2:D174, "2026-07-02", Master_Orders!J2:J174, "Partial COD") | G13: =SUMIFS(Master_Orders!E2:E174, Master_Orders!D2:D174, "2026-07-02", Master_Orders!J2:J174, "Prepaid") | H13: =COUNTIFS(Master_Orders!D2:D174, "2026-07-02", Master_Orders!J2:J174, "COD", Master_Orders!K2:K174, "Delivered") | I13: =COUNTIFS(Master_Orders!D2:D174, "2026-07-02", Master_Orders!J2:J174, "Partial COD", Master_Orders!K2:K174, "Delivered") | J13: =COUNTIFS(Master_Orders!D2:D174, "2026-07-02", Master_Orders!J2:J174, "Prepaid", Master_Orders!K2:K174, "Delivered") | K13: =COUNTIFS(Master_Orders!D2:D174, "2026-07-02", Master_Orders!J2:J174, "COD", Master_Orders!K2:K174, "RTO / Returned") | L13: =COUNTIFS(Master_Orders!D2:D174, "2026-07-02", Master_Orders!J2:J174, "Partial COD", Master_Orders!K2:K174, "RTO / Returned") | M13: =COUNTIFS(Master_Orders!D2:D174, "2026-07-02", Master_Orders!J2:J174, "Prepaid", Master_Orders!K2:K174, "RTO / Returned") | N13: =E13+F13+G13
A14: 2026-07-03 | B14: =COUNTIFS(Master_Orders!D2:D174, "2026-07-03", Master_Orders!J2:J174, "COD") | C14: =COUNTIFS(Master_Orders!D2:D174, "2026-07-03", Master_Orders!J2:J174, "Partial COD") | D14: =COUNTIFS(Master_Orders!D2:D174, "2026-07-03", Master_Orders!J2:J174, "Prepaid") | E14: =SUMIFS(Master_Orders!E2:E174, Master_Orders!D2:D174, "2026-07-03", Master_Orders!J2:J174, "COD") | F14: =SUMIFS(Master_Orders!E2:E174, Master_Orders!D2:D174, "2026-07-03", Master_Orders!J2:J174, "Partial COD") | G14: =SUMIFS(Master_Orders!E2:E174, Master_Orders!D2:D174, "2026-07-03", Master_Orders!J2:J174, "Prepaid") | H14: =COUNTIFS(Master_Orders!D2:D174, "2026-07-03", Master_Orders!J2:J174, "COD", Master_Orders!K2:K174, "Delivered") | I14: =COUNTIFS(Master_Orders!D2:D174, "2026-07-03", Master_Orders!J2:J174, "Partial COD", Master_Orders!K2:K174, "Delivered") | J14: =COUNTIFS(Master_Orders!D2:D174, "2026-07-03", Master_Orders!J2:J174, "Prepaid", Master_Orders!K2:K174, "Delivered") | K14: =COUNTIFS(Master_Orders!D2:D174, "2026-07-03", Master_Orders!J2:J174, "COD", Master_Orders!K2:K174, "RTO / Returned") | L14: =COUNTIFS(Master_Orders!D2:D174, "2026-07-03", Master_Orders!J2:J174, "Partial COD", Master_Orders!K2:K174, "RTO / Returned") | M14: =COUNTIFS(Master_Orders!D2:D174, "2026-07-03", Master_Orders!J2:J174, "Prepaid", Master_Orders!K2:K174, "RTO / Returned") | N14: =E14+F14+G14
A15: 2026-07-04 | B15: =COUNTIFS(Master_Orders!D2:D174, "2026-07-04", Master_Orders!J2:J174, "COD") | C15: =COUNTIFS(Master_Orders!D2:D174, "2026-07-04", Master_Orders!J2:J174, "Partial COD") | D15: =COUNTIFS(Master_Orders!D2:D174, "2026-07-04", Master_Orders!J2:J174, "Prepaid") | E15: =SUMIFS(Master_Orders!E2:E174, Master_Orders!D2:D174, "2026-07-04", Master_Orders!J2:J174, "COD") | F15: =SUMIFS(Master_Orders!E2:E174, Master_Orders!D2:D174, "2026-07-04", Master_Orders!J2:J174, "Partial COD") | G15: =SUMIFS(Master_Orders!E2:E174, Master_Orders!D2:D174, "2026-07-04", Master_Orders!J2:J174, "Prepaid") | H15: =COUNTIFS(Master_Orders!D2:D174, "2026-07-04", Master_Orders!J2:J174, "COD", Master_Orders!K2:K174, "Delivered") | I15: =COUNTIFS(Master_Orders!D2:D174, "2026-07-04", Master_Orders!J2:J174, "Partial COD", Master_Orders!K2:K174, "Delivered") | J15: =COUNTIFS(Master_Orders!D2:D174, "2026-07-04", Master_Orders!J2:J174, "Prepaid", Master_Orders!K2:K174, "Delivered") | K15: =COUNTIFS(Master_Orders!D2:D174, "2026-07-04", Master_Orders!J2:J174, "COD", Master_Orders!K2:K174, "RTO / Returned") | L15: =COUNTIFS(Master_Orders!D2:D174, "2026-07-04", Master_Orders!J2:J174, "Partial COD", Master_Orders!K2:K174, "RTO / Returned") | M15: =COUNTIFS(Master_Orders!D2:D174, "2026-07-04", Master_Orders!J2:J174, "Prepaid", Master_Orders!K2:K174, "RTO / Returned") | N15: =E15+F15+G15
A16: 2026-07-05 | B16: =COUNTIFS(Master_Orders!D2:D174, "2026-07-05", Master_Orders!J2:J174, "COD") | C16: =COUNTIFS(Master_Orders!D2:D174, "2026-07-05", Master_Orders!J2:J174, "Partial COD") | D16: =COUNTIFS(Master_Orders!D2:D174, "2026-07-05", Master_Orders!J2:J174, "Prepaid") | E16: =SUMIFS(Master_Orders!E2:E174, Master_Orders!D2:D174, "2026-07-05", Master_Orders!J2:J174, "COD") | F16: =SUMIFS(Master_Orders!E2:E174, Master_Orders!D2:D174, "2026-07-05", Master_Orders!J2:J174, "Partial COD") | G16: =SUMIFS(Master_Orders!E2:E174, Master_Orders!D2:D174, "2026-07-05", Master_Orders!J2:J174, "Prepaid") | H16: =COUNTIFS(Master_Orders!D2:D174, "2026-07-05", Master_Orders!J2:J174, "COD", Master_Orders!K2:K174, "Delivered") | I16: =COUNTIFS(Master_Orders!D2:D174, "2026-07-05", Master_Orders!J2:J174, "Partial COD", Master_Orders!K2:K174, "Delivered") | J16: =COUNTIFS(Master_Orders!D2:D174, "2026-07-05", Master_Orders!J2:J174, "Prepaid", Master_Orders!K2:K174, "Delivered") | K16: =COUNTIFS(Master_Orders!D2:D174, "2026-07-05", Master_Orders!J2:J174, "COD", Master_Orders!K2:K174, "RTO / Returned") | L16: =COUNTIFS(Master_Orders!D2:D174, "2026-07-05", Master_Orders!J2:J174, "Partial COD", Master_Orders!K2:K174, "RTO / Returned") | M16: =COUNTIFS(Master_Orders!D2:D174, "2026-07-05", Master_Orders!J2:J174, "Prepaid", Master_Orders!K2:K174, "RTO / Returned") | N16: =E16+F16+G16
A17: 2026-07-06 | B17: =COUNTIFS(Master_Orders!D2:D174, "2026-07-06", Master_Orders!J2:J174, "COD") | C17: =COUNTIFS(Master_Orders!D2:D174, "2026-07-06", Master_Orders!J2:J174, "Partial COD") | D17: =COUNTIFS(Master_Orders!D2:D174, "2026-07-06", Master_Orders!J2:J174, "Prepaid") | E17: =SUMIFS(Master_Orders!E2:E174, Master_Orders!D2:D174, "2026-07-06", Master_Orders!J2:J174, "COD") | F17: =SUMIFS(Master_Orders!E2:E174, Master_Orders!D2:D174, "2026-07-06", Master_Orders!J2:J174, "Partial COD") | G17: =SUMIFS(Master_Orders!E2:E174, Master_Orders!D2:D174, "2026-07-06", Master_Orders!J2:J174, "Prepaid") | H17: =COUNTIFS(Master_Orders!D2:D174, "2026-07-06", Master_Orders!J2:J174, "COD", Master_Orders!K2:K174, "Delivered") | I17: =COUNTIFS(Master_Orders!D2:D174, "2026-07-06", Master_Orders!J2:J174, "Partial COD", Master_Orders!K2:K174, "Delivered") | J17: =COUNTIFS(Master_Orders!D2:D174, "2026-07-06", Master_Orders!J2:J174, "Prepaid", Master_Orders!K2:K174, "Delivered") | K17: =COUNTIFS(Master_Orders!D2:D174, "2026-07-06", Master_Orders!J2:J174, "COD", Master_Orders!K2:K174, "RTO / Returned") | L17: =COUNTIFS(Master_Orders!D2:D174, "2026-07-06", Master_Orders!J2:J174, "Partial COD", Master_Orders!K2:K174, "RTO / Returned") | M17: =COUNTIFS(Master_Orders!D2:D174, "2026-07-06", Master_Orders!J2:J174, "Prepaid", Master_Orders!K2:K174, "RTO / Returned") | N17: =E17+F17+G17
A18: 2026-07-07 | B18: =COUNTIFS(Master_Orders!D2:D174, "2026-07-07", Master_Orders!J2:J174, "COD") | C18: =COUNTIFS(Master_Orders!D2:D174, "2026-07-07", Master_Orders!J2:J174, "Partial COD") | D18: =COUNTIFS(Master_Orders!D2:D174, "2026-07-07", Master_Orders!J2:J174, "Prepaid") | E18: =SUMIFS(Master_Orders!E2:E174, Master_Orders!D2:D174, "2026-07-07", Master_Orders!J2:J174, "COD") | F18: =SUMIFS(Master_Orders!E2:E174, Master_Orders!D2:D174, "2026-07-07", Master_Orders!J2:J174, "Partial COD") | G18: =SUMIFS(Master_Orders!E2:E174, Master_Orders!D2:D174, "2026-07-07", Master_Orders!J2:J174, "Prepaid") | H18: =COUNTIFS(Master_Orders!D2:D174, "2026-07-07", Master_Orders!J2:J174, "COD", Master_Orders!K2:K174, "Delivered") | I18: =COUNTIFS(Master_Orders!D2:D174, "2026-07-07", Master_Orders!J2:J174, "Partial COD", Master_Orders!K2:K174, "Delivered") | J18: =COUNTIFS(Master_Orders!D2:D174, "2026-07-07", Master_Orders!J2:J174, "Prepaid", Master_Orders!K2:K174, "Delivered") | K18: =COUNTIFS(Master_Orders!D2:D174, "2026-07-07", Master_Orders!J2:J174, "COD", Master_Orders!K2:K174, "RTO / Returned") | L18: =COUNTIFS(Master_Orders!D2:D174, "2026-07-07", Master_Orders!J2:J174, "Partial COD", Master_Orders!K2:K174, "RTO / Returned") | M18: =COUNTIFS(Master_Orders!D2:D174, "2026-07-07", Master_Orders!J2:J174, "Prepaid", Master_Orders!K2:K174, "RTO / Returned") | N18: =E18+F18+G18
A19: 2026-07-08 | B19: =COUNTIFS(Master_Orders!D2:D174, "2026-07-08", Master_Orders!J2:J174, "COD") | C19: =COUNTIFS(Master_Orders!D2:D174, "2026-07-08", Master_Orders!J2:J174, "Partial COD") | D19: =COUNTIFS(Master_Orders!D2:D174, "2026-07-08", Master_Orders!J2:J174, "Prepaid") | E19: =SUMIFS(Master_Orders!E2:E174, Master_Orders!D2:D174, "2026-07-08", Master_Orders!J2:J174, "COD") | F19: =SUMIFS(Master_Orders!E2:E174, Master_Orders!D2:D174, "2026-07-08", Master_Orders!J2:J174, "Partial COD") | G19: =SUMIFS(Master_Orders!E2:E174, Master_Orders!D2:D174, "2026-07-08", Master_Orders!J2:J174, "Prepaid") | H19: =COUNTIFS(Master_Orders!D2:D174, "2026-07-08", Master_Orders!J2:J174, "COD", Master_Orders!K2:K174, "Delivered") | I19: =COUNTIFS(Master_Orders!D2:D174, "2026-07-08", Master_Orders!J2:J174, "Partial COD", Master_Orders!K2:K174, "Delivered") | J19: =COUNTIFS(Master_Orders!D2:D174, "2026-07-08", Master_Orders!J2:J174, "Prepaid", Master_Orders!K2:K174, "Delivered") | K19: =COUNTIFS(Master_Orders!D2:D174, "2026-07-08", Master_Orders!J2:J174, "COD", Master_Orders!K2:K174, "RTO / Returned") | L19: =COUNTIFS(Master_Orders!D2:D174, "2026-07-08", Master_Orders!J2:J174, "Partial COD", Master_Orders!K2:K174, "RTO / Returned") | M19: =COUNTIFS(Master_Orders!D2:D174, "2026-07-08", Master_Orders!J2:J174, "Prepaid", Master_Orders!K2:K174, "RTO / Returned") | N19: =E19+F19+G19
A20: 2026-07-09 | B20: =COUNTIFS(Master_Orders!D2:D174, "2026-07-09", Master_Orders!J2:J174, "COD") | C20: =COUNTIFS(Master_Orders!D2:D174, "2026-07-09", Master_Orders!J2:J174, "Partial COD") | D20: =COUNTIFS(Master_Orders!D2:D174, "2026-07-09", Master_Orders!J2:J174, "Prepaid") | E20: =SUMIFS(Master_Orders!E2:E174, Master_Orders!D2:D174, "2026-07-09", Master_Orders!J2:J174, "COD") | F20: =SUMIFS(Master_Orders!E2:E174, Master_Orders!D2:D174, "2026-07-09", Master_Orders!J2:J174, "Partial COD") | G20: =SUMIFS(Master_Orders!E2:E174, Master_Orders!D2:D174, "2026-07-09", Master_Orders!J2:J174, "Prepaid") | H20: =COUNTIFS(Master_Orders!D2:D174, "2026-07-09", Master_Orders!J2:J174, "COD", Master_Orders!K2:K174, "Delivered") | I20: =COUNTIFS(Master_Orders!D2:D174, "2026-07-09", Master_Orders!J2:J174, "Partial COD", Master_Orders!K2:K174, "Delivered") | J20: =COUNTIFS(Master_Orders!D2:D174, "2026-07-09", Master_Orders!J2:J174, "Prepaid", Master_Orders!K2:K174, "Delivered") | K20: =COUNTIFS(Master_Orders!D2:D174, "2026-07-09", Master_Orders!J2:J174, "COD", Master_Orders!K2:K174, "RTO / Returned") | L20: =COUNTIFS(Master_Orders!D2:D174, "2026-07-09", Master_Orders!J2:J174, "Partial COD", Master_Orders!K2:K174, "RTO / Returned") | M20: =COUNTIFS(Master_Orders!D2:D174, "2026-07-09", Master_Orders!J2:J174, "Prepaid", Master_Orders!K2:K174, "RTO / Returned") | N20: =E20+F20+G20
A21: 2026-07-10 | B21: =COUNTIFS(Master_Orders!D2:D174, "2026-07-10", Master_Orders!J2:J174, "COD") | C21: =COUNTIFS(Master_Orders!D2:D174, "2026-07-10", Master_Orders!J2:J174, "Partial COD") | D21: =COUNTIFS(Master_Orders!D2:D174, "2026-07-10", Master_Orders!J2:J174, "Prepaid") | E21: =SUMIFS(Master_Orders!E2:E174, Master_Orders!D2:D174, "2026-07-10", Master_Orders!J2:J174, "COD") | F21: =SUMIFS(Master_Orders!E2:E174, Master_Orders!D2:D174, "2026-07-10", Master_Orders!J2:J174, "Partial COD") | G21: =SUMIFS(Master_Orders!E2:E174, Master_Orders!D2:D174, "2026-07-10", Master_Orders!J2:J174, "Prepaid") | H21: =COUNTIFS(Master_Orders!D2:D174, "2026-07-10", Master_Orders!J2:J174, "COD", Master_Orders!K2:K174, "Delivered") | I21: =COUNTIFS(Master_Orders!D2:D174, "2026-07-10", Master_Orders!J2:J174, "Partial COD", Master_Orders!K2:K174, "Delivered") | J21: =COUNTIFS(Master_Orders!D2:D174, "2026-07-10", Master_Orders!J2:J174, "Prepaid", Master_Orders!K2:K174, "Delivered") | K21: =COUNTIFS(Master_Orders!D2:D174, "2026-07-10", Master_Orders!J2:J174, "COD", Master_Orders!K2:K174, "RTO / Returned") | L21: =COUNTIFS(Master_Orders!D2:D174, "2026-07-10", Master_Orders!J2:J174, "Partial COD", Master_Orders!K2:K174, "RTO / Returned") | M21: =COUNTIFS(Master_Orders!D2:D174, "2026-07-10", Master_Orders!J2:J174, "Prepaid", Master_Orders!K2:K174, "RTO / Returned") | N21: =E21+F21+G21
A22: 2026-07-11 | B22: =COUNTIFS(Master_Orders!D2:D174, "2026-07-11", Master_Orders!J2:J174, "COD") | C22: =COUNTIFS(Master_Orders!D2:D174, "2026-07-11", Master_Orders!J2:J174, "Partial COD") | D22: =COUNTIFS(Master_Orders!D2:D174, "2026-07-11", Master_Orders!J2:J174, "Prepaid") | E22: =SUMIFS(Master_Orders!E2:E174, Master_Orders!D2:D174, "2026-07-11", Master_Orders!J2:J174, "COD") | F22: =SUMIFS(Master_Orders!E2:E174, Master_Orders!D2:D174, "2026-07-11", Master_Orders!J2:J174, "Partial COD") | G22: =SUMIFS(Master_Orders!E2:E174, Master_Orders!D2:D174, "2026-07-11", Master_Orders!J2:J174, "Prepaid") | H22: =COUNTIFS(Master_Orders!D2:D174, "2026-07-11", Master_Orders!J2:J174, "COD", Master_Orders!K2:K174, "Delivered") | I22: =COUNTIFS(Master_Orders!D2:D174, "2026-07-11", Master_Orders!J2:J174, "Partial COD", Master_Orders!K2:K174, "Delivered") | J22: =COUNTIFS(Master_Orders!D2:D174, "2026-07-11", Master_Orders!J2:J174, "Prepaid", Master_Orders!K2:K174, "Delivered") | K22: =COUNTIFS(Master_Orders!D2:D174, "2026-07-11", Master_Orders!J2:J174, "COD", Master_Orders!K2:K174, "RTO / Returned") | L22: =COUNTIFS(Master_Orders!D2:D174, "2026-07-11", Master_Orders!J2:J174, "Partial COD", Master_Orders!K2:K174, "RTO / Returned") | M22: =COUNTIFS(Master_Orders!D2:D174, "2026-07-11", Master_Orders!J2:J174, "Prepaid", Master_Orders!K2:K174, "RTO / Returned") | N22: =E22+F22+G22
A23: 2026-07-12 | B23: =COUNTIFS(Master_Orders!D2:D174, "2026-07-12", Master_Orders!J2:J174, "COD") | C23: =COUNTIFS(Master_Orders!D2:D174, "2026-07-12", Master_Orders!J2:J174, "Partial COD") | D23: =COUNTIFS(Master_Orders!D2:D174, "2026-07-12", Master_Orders!J2:J174, "Prepaid") | E23: =SUMIFS(Master_Orders!E2:E174, Master_Orders!D2:D174, "2026-07-12", Master_Orders!J2:J174, "COD") | F23: =SUMIFS(Master_Orders!E2:E174, Master_Orders!D2:D174, "2026-07-12", Master_Orders!J2:J174, "Partial COD") | G23: =SUMIFS(Master_Orders!E2:E174, Master_Orders!D2:D174, "2026-07-12", Master_Orders!J2:J174, "Prepaid") | H23: =COUNTIFS(Master_Orders!D2:D174, "2026-07-12", Master_Orders!J2:J174, "COD", Master_Orders!K2:K174, "Delivered") | I23: =COUNTIFS(Master_Orders!D2:D174, "2026-07-12", Master_Orders!J2:J174, "Partial COD", Master_Orders!K2:K174, "Delivered") | J23: =COUNTIFS(Master_Orders!D2:D174, "2026-07-12", Master_Orders!J2:J174, "Prepaid", Master_Orders!K2:K174, "Delivered") | K23: =COUNTIFS(Master_Orders!D2:D174, "2026-07-12", Master_Orders!J2:J174, "COD", Master_Orders!K2:K174, "RTO / Returned") | L23: =COUNTIFS(Master_Orders!D2:D174, "2026-07-12", Master_Orders!J2:J174, "Partial COD", Master_Orders!K2:K174, "RTO / Returned") | M23: =COUNTIFS(Master_Orders!D2:D174, "2026-07-12", Master_Orders!J2:J174, "Prepaid", Master_Orders!K2:K174, "RTO / Returned") | N23: =E23+F23+G23
A24: 2026-07-13 | B24: =COUNTIFS(Master_Orders!D2:D174, "2026-07-13", Master_Orders!J2:J174, "COD") | C24: =COUNTIFS(Master_Orders!D2:D174, "2026-07-13", Master_Orders!J2:J174, "Partial COD") | D24: =COUNTIFS(Master_Orders!D2:D174, "2026-07-13", Master_Orders!J2:J174, "Prepaid") | E24: =SUMIFS(Master_Orders!E2:E174, Master_Orders!D2:D174, "2026-07-13", Master_Orders!J2:J174, "COD") | F24: =SUMIFS(Master_Orders!E2:E174, Master_Orders!D2:D174, "2026-07-13", Master_Orders!J2:J174, "Partial COD") | G24: =SUMIFS(Master_Orders!E2:E174, Master_Orders!D2:D174, "2026-07-13", Master_Orders!J2:J174, "Prepaid") | H24: =COUNTIFS(Master_Orders!D2:D174, "2026-07-13", Master_Orders!J2:J174, "COD", Master_Orders!K2:K174, "Delivered") | I24: =COUNTIFS(Master_Orders!D2:D174, "2026-07-13", Master_Orders!J2:J174, "Partial COD", Master_Orders!K2:K174, "Delivered") | J24: =COUNTIFS(Master_Orders!D2:D174, "2026-07-13", Master_Orders!J2:J174, "Prepaid", Master_Orders!K2:K174, "Delivered") | K24: =COUNTIFS(Master_Orders!D2:D174, "2026-07-13", Master_Orders!J2:J174, "COD", Master_Orders!K2:K174, "RTO / Returned") | L24: =COUNTIFS(Master_Orders!D2:D174, "2026-07-13", Master_Orders!J2:J174, "Partial COD", Master_Orders!K2:K174, "RTO / Returned") | M24: =COUNTIFS(Master_Orders!D2:D174, "2026-07-13", Master_Orders!J2:J174, "Prepaid", Master_Orders!K2:K174, "RTO / Returned") | N24: =E24+F24+G24
A25: 2026-07-14 | B25: =COUNTIFS(Master_Orders!D2:D174, "2026-07-14", Master_Orders!J2:J174, "COD") | C25: =COUNTIFS(Master_Orders!D2:D174, "2026-07-14", Master_Orders!J2:J174, "Partial COD") | D25: =COUNTIFS(Master_Orders!D2:D174, "2026-07-14", Master_Orders!J2:J174, "Prepaid") | E25: =SUMIFS(Master_Orders!E2:E174, Master_Orders!D2:D174, "2026-07-14", Master_Orders!J2:J174, "COD") | F25: =SUMIFS(Master_Orders!E2:E174, Master_Orders!D2:D174, "2026-07-14", Master_Orders!J2:J174, "Partial COD") | G25: =SUMIFS(Master_Orders!E2:E174, Master_Orders!D2:D174, "2026-07-14", Master_Orders!J2:J174, "Prepaid") | H25: =COUNTIFS(Master_Orders!D2:D174, "2026-07-14", Master_Orders!J2:J174, "COD", Master_Orders!K2:K174, "Delivered") | I25: =COUNTIFS(Master_Orders!D2:D174, "2026-07-14", Master_Orders!J2:J174, "Partial COD", Master_Orders!K2:K174, "Delivered") | J25: =COUNTIFS(Master_Orders!D2:D174, "2026-07-14", Master_Orders!J2:J174, "Prepaid", Master_Orders!K2:K174, "Delivered") | K25: =COUNTIFS(Master_Orders!D2:D174, "2026-07-14", Master_Orders!J2:J174, "COD", Master_Orders!K2:K174, "RTO / Returned") | L25: =COUNTIFS(Master_Orders!D2:D174, "2026-07-14", Master_Orders!J2:J174, "Partial COD", Master_Orders!K2:K174, "RTO / Returned") | M25: =COUNTIFS(Master_Orders!D2:D174, "2026-07-14", Master_Orders!J2:J174, "Prepaid", Master_Orders!K2:K174, "RTO / Returned") | N25: =E25+F25+G25
A26: 2026-07-15 | B26: =COUNTIFS(Master_Orders!D2:D174, "2026-07-15", Master_Orders!J2:J174, "COD") | C26: =COUNTIFS(Master_Orders!D2:D174, "2026-07-15", Master_Orders!J2:J174, "Partial COD") | D26: =COUNTIFS(Master_Orders!D2:D174, "2026-07-15", Master_Orders!J2:J174, "Prepaid") | E26: =SUMIFS(Master_Orders!E2:E174, Master_Orders!D2:D174, "2026-07-15", Master_Orders!J2:J174, "COD") | F26: =SUMIFS(Master_Orders!E2:E174, Master_Orders!D2:D174, "2026-07-15", Master_Orders!J2:J174, "Partial COD") | G26: =SUMIFS(Master_Orders!E2:E174, Master_Orders!D2:D174, "2026-07-15", Master_Orders!J2:J174, "Prepaid") | H26: =COUNTIFS(Master_Orders!D2:D174, "2026-07-15", Master_Orders!J2:J174, "COD", Master_Orders!K2:K174, "Delivered") | I26: =COUNTIFS(Master_Orders!D2:D174, "2026-07-15", Master_Orders!J2:J174, "Partial COD", Master_Orders!K2:K174, "Delivered") | J26: =COUNTIFS(Master_Orders!D2:D174, "2026-07-15", Master_Orders!J2:J174, "Prepaid", Master_Orders!K2:K174, "Delivered") | K26: =COUNTIFS(Master_Orders!D2:D174, "2026-07-15", Master_Orders!J2:J174, "COD", Master_Orders!K2:K174, "RTO / Returned") | L26: =COUNTIFS(Master_Orders!D2:D174, "2026-07-15", Master_Orders!J2:J174, "Partial COD", Master_Orders!K2:K174, "RTO / Returned") | M26: =COUNTIFS(Master_Orders!D2:D174, "2026-07-15", Master_Orders!J2:J174, "Prepaid", Master_Orders!K2:K174, "RTO / Returned") | N26: =E26+F26+G26
A27: 2026-07-16 | B27: =COUNTIFS(Master_Orders!D2:D174, "2026-07-16", Master_Orders!J2:J174, "COD") | C27: =COUNTIFS(Master_Orders!D2:D174, "2026-07-16", Master_Orders!J2:J174, "Partial COD") | D27: =COUNTIFS(Master_Orders!D2:D174, "2026-07-16", Master_Orders!J2:J174, "Prepaid") | E27: =SUMIFS(Master_Orders!E2:E174, Master_Orders!D2:D174, "2026-07-16", Master_Orders!J2:J174, "COD") | F27: =SUMIFS(Master_Orders!E2:E174, Master_Orders!D2:D174, "2026-07-16", Master_Orders!J2:J174, "Partial COD") | G27: =SUMIFS(Master_Orders!E2:E174, Master_Orders!D2:D174, "2026-07-16", Master_Orders!J2:J174, "Prepaid") | H27: =COUNTIFS(Master_Orders!D2:D174, "2026-07-16", Master_Orders!J2:J174, "COD", Master_Orders!K2:K174, "Delivered") | I27: =COUNTIFS(Master_Orders!D2:D174, "2026-07-16", Master_Orders!J2:J174, "Partial COD", Master_Orders!K2:K174, "Delivered") | J27: =COUNTIFS(Master_Orders!D2:D174, "2026-07-16", Master_Orders!J2:J174, "Prepaid", Master_Orders!K2:K174, "Delivered") | K27: =COUNTIFS(Master_Orders!D2:D174, "2026-07-16", Master_Orders!J2:J174, "COD", Master_Orders!K2:K174, "RTO / Returned") | L27: =COUNTIFS(Master_Orders!D2:D174, "2026-07-16", Master_Orders!J2:J174, "Partial COD", Master_Orders!K2:K174, "RTO / Returned") | M27: =COUNTIFS(Master_Orders!D2:D174, "2026-07-16", Master_Orders!J2:J174, "Prepaid", Master_Orders!K2:K174, "RTO / Returned") | N27: =E27+F27+G27
A28: 2026-07-17 | B28: =COUNTIFS(Master_Orders!D2:D174, "2026-07-17", Master_Orders!J2:J174, "COD") | C28: =COUNTIFS(Master_Orders!D2:D174, "2026-07-17", Master_Orders!J2:J174, "Partial COD") | D28: =COUNTIFS(Master_Orders!D2:D174, "2026-07-17", Master_Orders!J2:J174, "Prepaid") | E28: =SUMIFS(Master_Orders!E2:E174, Master_Orders!D2:D174, "2026-07-17", Master_Orders!J2:J174, "COD") | F28: =SUMIFS(Master_Orders!E2:E174, Master_Orders!D2:D174, "2026-07-17", Master_Orders!J2:J174, "Partial COD") | G28: =SUMIFS(Master_Orders!E2:E174, Master_Orders!D2:D174, "2026-07-17", Master_Orders!J2:J174, "Prepaid") | H28: =COUNTIFS(Master_Orders!D2:D174, "2026-07-17", Master_Orders!J2:J174, "COD", Master_Orders!K2:K174, "Delivered") | I28: =COUNTIFS(Master_Orders!D2:D174, "2026-07-17", Master_Orders!J2:J174, "Partial COD", Master_Orders!K2:K174, "Delivered") | J28: =COUNTIFS(Master_Orders!D2:D174, "2026-07-17", Master_Orders!J2:J174, "Prepaid", Master_Orders!K2:K174, "Delivered") | K28: =COUNTIFS(Master_Orders!D2:D174, "2026-07-17", Master_Orders!J2:J174, "COD", Master_Orders!K2:K174, "RTO / Returned") | L28: =COUNTIFS(Master_Orders!D2:D174, "2026-07-17", Master_Orders!J2:J174, "Partial COD", Master_Orders!K2:K174, "RTO / Returned") | M28: =COUNTIFS(Master_Orders!D2:D174, "2026-07-17", Master_Orders!J2:J174, "Prepaid", Master_Orders!K2:K174, "RTO / Returned") | N28: =E28+F28+G28
A29: 2026-07-18 | B29: =COUNTIFS(Master_Orders!D2:D174, "2026-07-18", Master_Orders!J2:J174, "COD") | C29: =COUNTIFS(Master_Orders!D2:D174, "2026-07-18", Master_Orders!J2:J174, "Partial COD") | D29: =COUNTIFS(Master_Orders!D2:D174, "2026-07-18", Master_Orders!J2:J174, "Prepaid") | E29: =SUMIFS(Master_Orders!E2:E174, Master_Orders!D2:D174, "2026-07-18", Master_Orders!J2:J174, "COD") | F29: =SUMIFS(Master_Orders!E2:E174, Master_Orders!D2:D174, "2026-07-18", Master_Orders!J2:J174, "Partial COD") | G29: =SUMIFS(Master_Orders!E2:E174, Master_Orders!D2:D174, "2026-07-18", Master_Orders!J2:J174, "Prepaid") | H29: =COUNTIFS(Master_Orders!D2:D174, "2026-07-18", Master_Orders!J2:J174, "COD", Master_Orders!K2:K174, "Delivered") | I29: =COUNTIFS(Master_Orders!D2:D174, "2026-07-18", Master_Orders!J2:J174, "Partial COD", Master_Orders!K2:K174, "Delivered") | J29: =COUNTIFS(Master_Orders!D2:D174, "2026-07-18", Master_Orders!J2:J174, "Prepaid", Master_Orders!K2:K174, "Delivered") | K29: =COUNTIFS(Master_Orders!D2:D174, "2026-07-18", Master_Orders!J2:J174, "COD", Master_Orders!K2:K174, "RTO / Returned") | L29: =COUNTIFS(Master_Orders!D2:D174, "2026-07-18", Master_Orders!J2:J174, "Partial COD", Master_Orders!K2:K174, "RTO / Returned") | M29: =COUNTIFS(Master_Orders!D2:D174, "2026-07-18", Master_Orders!J2:J174, "Prepaid", Master_Orders!K2:K174, "RTO / Returned") | N29: =E29+F29+G29
A30: 2026-07-19 | B30: =COUNTIFS(Master_Orders!D2:D174, "2026-07-19", Master_Orders!J2:J174, "COD") | C30: =COUNTIFS(Master_Orders!D2:D174, "2026-07-19", Master_Orders!J2:J174, "Partial COD") | D30: =COUNTIFS(Master_Orders!D2:D174, "2026-07-19", Master_Orders!J2:J174, "Prepaid") | E30: =SUMIFS(Master_Orders!E2:E174, Master_Orders!D2:D174, "2026-07-19", Master_Orders!J2:J174, "COD") | F30: =SUMIFS(Master_Orders!E2:E174, Master_Orders!D2:D174, "2026-07-19", Master_Orders!J2:J174, "Partial COD") | G30: =SUMIFS(Master_Orders!E2:E174, Master_Orders!D2:D174, "2026-07-19", Master_Orders!J2:J174, "Prepaid") | H30: =COUNTIFS(Master_Orders!D2:D174, "2026-07-19", Master_Orders!J2:J174, "COD", Master_Orders!K2:K174, "Delivered") | I30: =COUNTIFS(Master_Orders!D2:D174, "2026-07-19", Master_Orders!J2:J174, "Partial COD", Master_Orders!K2:K174, "Delivered") | J30: =COUNTIFS(Master_Orders!D2:D174, "2026-07-19", Master_Orders!J2:J174, "Prepaid", Master_Orders!K2:K174, "Delivered") | K30: =COUNTIFS(Master_Orders!D2:D174, "2026-07-19", Master_Orders!J2:J174, "COD", Master_Orders!K2:K174, "RTO / Returned") | L30: =COUNTIFS(Master_Orders!D2:D174, "2026-07-19", Master_Orders!J2:J174, "Partial COD", Master_Orders!K2:K174, "RTO / Returned") | M30: =COUNTIFS(Master_Orders!D2:D174, "2026-07-19", Master_Orders!J2:J174, "Prepaid", Master_Orders!K2:K174, "RTO / Returned") | N30: =E30+F30+G30
A31: 2026-07-20 | B31: =COUNTIFS(Master_Orders!D2:D174, "2026-07-20", Master_Orders!J2:J174, "COD") | C31: =COUNTIFS(Master_Orders!D2:D174, "2026-07-20", Master_Orders!J2:J174, "Partial COD") | D31: =COUNTIFS(Master_Orders!D2:D174, "2026-07-20", Master_Orders!J2:J174, "Prepaid") | E31: =SUMIFS(Master_Orders!E2:E174, Master_Orders!D2:D174, "2026-07-20", Master_Orders!J2:J174, "COD") | F31: =SUMIFS(Master_Orders!E2:E174, Master_Orders!D2:D174, "2026-07-20", Master_Orders!J2:J174, "Partial COD") | G31: =SUMIFS(Master_Orders!E2:E174, Master_Orders!D2:D174, "2026-07-20", Master_Orders!J2:J174, "Prepaid") | H31: =COUNTIFS(Master_Orders!D2:D174, "2026-07-20", Master_Orders!J2:J174, "COD", Master_Orders!K2:K174, "Delivered") | I31: =COUNTIFS(Master_Orders!D2:D174, "2026-07-20", Master_Orders!J2:J174, "Partial COD", Master_Orders!K2:K174, "Delivered") | J31: =COUNTIFS(Master_Orders!D2:D174, "2026-07-20", Master_Orders!J2:J174, "Prepaid", Master_Orders!K2:K174, "Delivered") | K31: =COUNTIFS(Master_Orders!D2:D174, "2026-07-20", Master_Orders!J2:J174, "COD", Master_Orders!K2:K174, "RTO / Returned") | L31: =COUNTIFS(Master_Orders!D2:D174, "2026-07-20", Master_Orders!J2:J174, "Partial COD", Master_Orders!K2:K174, "RTO / Returned") | M31: =COUNTIFS(Master_Orders!D2:D174, "2026-07-20", Master_Orders!J2:J174, "Prepaid", Master_Orders!K2:K174, "RTO / Returned") | N31: =E31+F31+G31
A32: 2026-07-21 | B32: =COUNTIFS(Master_Orders!D2:D174, "2026-07-21", Master_Orders!J2:J174, "COD") | C32: =COUNTIFS(Master_Orders!D2:D174, "2026-07-21", Master_Orders!J2:J174, "Partial COD") | D32: =COUNTIFS(Master_Orders!D2:D174, "2026-07-21", Master_Orders!J2:J174, "Prepaid") | E32: =SUMIFS(Master_Orders!E2:E174, Master_Orders!D2:D174, "2026-07-21", Master_Orders!J2:J174, "COD") | F32: =SUMIFS(Master_Orders!E2:E174, Master_Orders!D2:D174, "2026-07-21", Master_Orders!J2:J174, "Partial COD") | G32: =SUMIFS(Master_Orders!E2:E174, Master_Orders!D2:D174, "2026-07-21", Master_Orders!J2:J174, "Prepaid") | H32: =COUNTIFS(Master_Orders!D2:D174, "2026-07-21", Master_Orders!J2:J174, "COD", Master_Orders!K2:K174, "Delivered") | I32: =COUNTIFS(Master_Orders!D2:D174, "2026-07-21", Master_Orders!J2:J174, "Partial COD", Master_Orders!K2:K174, "Delivered") | J32: =COUNTIFS(Master_Orders!D2:D174, "2026-07-21", Master_Orders!J2:J174, "Prepaid", Master_Orders!K2:K174, "Delivered") | K32: =COUNTIFS(Master_Orders!D2:D174, "2026-07-21", Master_Orders!J2:J174, "COD", Master_Orders!K2:K174, "RTO / Returned") | L32: =COUNTIFS(Master_Orders!D2:D174, "2026-07-21", Master_Orders!J2:J174, "Partial COD", Master_Orders!K2:K174, "RTO / Returned") | M32: =COUNTIFS(Master_Orders!D2:D174, "2026-07-21", Master_Orders!J2:J174, "Prepaid", Master_Orders!K2:K174, "RTO / Returned") | N32: =E32+F32+G32
A33: 2026-07-22 | B33: =COUNTIFS(Master_Orders!D2:D174, "2026-07-22", Master_Orders!J2:J174, "COD") | C33: =COUNTIFS(Master_Orders!D2:D174, "2026-07-22", Master_Orders!J2:J174, "Partial COD") | D33: =COUNTIFS(Master_Orders!D2:D174, "2026-07-22", Master_Orders!J2:J174, "Prepaid") | E33: =SUMIFS(Master_Orders!E2:E174, Master_Orders!D2:D174, "2026-07-22", Master_Orders!J2:J174, "COD") | F33: =SUMIFS(Master_Orders!E2:E174, Master_Orders!D2:D174, "2026-07-22", Master_Orders!J2:J174, "Partial COD") | G33: =SUMIFS(Master_Orders!E2:E174, Master_Orders!D2:D174, "2026-07-22", Master_Orders!J2:J174, "Prepaid") | H33: =COUNTIFS(Master_Orders!D2:D174, "2026-07-22", Master_Orders!J2:J174, "COD", Master_Orders!K2:K174, "Delivered") | I33: =COUNTIFS(Master_Orders!D2:D174, "2026-07-22", Master_Orders!J2:J174, "Partial COD", Master_Orders!K2:K174, "Delivered") | J33: =COUNTIFS(Master_Orders!D2:D174, "2026-07-22", Master_Orders!J2:J174, "Prepaid", Master_Orders!K2:K174, "Delivered") | K33: =COUNTIFS(Master_Orders!D2:D174, "2026-07-22", Master_Orders!J2:J174, "COD", Master_Orders!K2:K174, "RTO / Returned") | L33: =COUNTIFS(Master_Orders!D2:D174, "2026-07-22", Master_Orders!J2:J174, "Partial COD", Master_Orders!K2:K174, "RTO / Returned") | M33: =COUNTIFS(Master_Orders!D2:D174, "2026-07-22", Master_Orders!J2:J174, "Prepaid", Master_Orders!K2:K174, "RTO / Returned") | N33: =E33+F33+G33
A34: 2026-07-23 | B34: =COUNTIFS(Master_Orders!D2:D174, "2026-07-23", Master_Orders!J2:J174, "COD") | C34: =COUNTIFS(Master_Orders!D2:D174, "2026-07-23", Master_Orders!J2:J174, "Partial COD") | D34: =COUNTIFS(Master_Orders!D2:D174, "2026-07-23", Master_Orders!J2:J174, "Prepaid") | E34: =SUMIFS(Master_Orders!E2:E174, Master_Orders!D2:D174, "2026-07-23", Master_Orders!J2:J174, "COD") | F34: =SUMIFS(Master_Orders!E2:E174, Master_Orders!D2:D174, "2026-07-23", Master_Orders!J2:J174, "Partial COD") | G34: =SUMIFS(Master_Orders!E2:E174, Master_Orders!D2:D174, "2026-07-23", Master_Orders!J2:J174, "Prepaid") | H34: =COUNTIFS(Master_Orders!D2:D174, "2026-07-23", Master_Orders!J2:J174, "COD", Master_Orders!K2:K174, "Delivered") | I34: =COUNTIFS(Master_Orders!D2:D174, "2026-07-23", Master_Orders!J2:J174, "Partial COD", Master_Orders!K2:K174, "Delivered") | J34: =COUNTIFS(Master_Orders!D2:D174, "2026-07-23", Master_Orders!J2:J174, "Prepaid", Master_Orders!K2:K174, "Delivered") | K34: =COUNTIFS(Master_Orders!D2:D174, "2026-07-23", Master_Orders!J2:J174, "COD", Master_Orders!K2:K174, "RTO / Returned") | L34: =COUNTIFS(Master_Orders!D2:D174, "2026-07-23", Master_Orders!J2:J174, "Partial COD", Master_Orders!K2:K174, "RTO / Returned") | M34: =COUNTIFS(Master_Orders!D2:D174, "2026-07-23", Master_Orders!J2:J174, "Prepaid", Master_Orders!K2:K174, "RTO / Returned") | N34: =E34+F34+G34
A35: 2026-07-24 | B35: =COUNTIFS(Master_Orders!D2:D174, "2026-07-24", Master_Orders!J2:J174, "COD") | C35: =COUNTIFS(Master_Orders!D2:D174, "2026-07-24", Master_Orders!J2:J174, "Partial COD") | D35: =COUNTIFS(Master_Orders!D2:D174, "2026-07-24", Master_Orders!J2:J174, "Prepaid") | E35: =SUMIFS(Master_Orders!E2:E174, Master_Orders!D2:D174, "2026-07-24", Master_Orders!J2:J174, "COD") | F35: =SUMIFS(Master_Orders!E2:E174, Master_Orders!D2:D174, "2026-07-24", Master_Orders!J2:J174, "Partial COD") | G35: =SUMIFS(Master_Orders!E2:E174, Master_Orders!D2:D174, "2026-07-24", Master_Orders!J2:J174, "Prepaid") | H35: =COUNTIFS(Master_Orders!D2:D174, "2026-07-24", Master_Orders!J2:J174, "COD", Master_Orders!K2:K174, "Delivered") | I35: =COUNTIFS(Master_Orders!D2:D174, "2026-07-24", Master_Orders!J2:J174, "Partial COD", Master_Orders!K2:K174, "Delivered") | J35: =COUNTIFS(Master_Orders!D2:D174, "2026-07-24", Master_Orders!J2:J174, "Prepaid", Master_Orders!K2:K174, "Delivered") | K35: =COUNTIFS(Master_Orders!D2:D174, "2026-07-24", Master_Orders!J2:J174, "COD", Master_Orders!K2:K174, "RTO / Returned") | L35: =COUNTIFS(Master_Orders!D2:D174, "2026-07-24", Master_Orders!J2:J174, "Partial COD", Master_Orders!K2:K174, "RTO / Returned") | M35: =COUNTIFS(Master_Orders!D2:D174, "2026-07-24", Master_Orders!J2:J174, "Prepaid", Master_Orders!K2:K174, "RTO / Returned") | N35: =E35+F35+G35
A36: 2026-07-25 | B36: =COUNTIFS(Master_Orders!D2:D174, "2026-07-25", Master_Orders!J2:J174, "COD") | C36: =COUNTIFS(Master_Orders!D2:D174, "2026-07-25", Master_Orders!J2:J174, "Partial COD") | D36: =COUNTIFS(Master_Orders!D2:D174, "2026-07-25", Master_Orders!J2:J174, "Prepaid") | E36: =SUMIFS(Master_Orders!E2:E174, Master_Orders!D2:D174, "2026-07-25", Master_Orders!J2:J174, "COD") | F36: =SUMIFS(Master_Orders!E2:E174, Master_Orders!D2:D174, "2026-07-25", Master_Orders!J2:J174, "Partial COD") | G36: =SUMIFS(Master_Orders!E2:E174, Master_Orders!D2:D174, "2026-07-25", Master_Orders!J2:J174, "Prepaid") | H36: =COUNTIFS(Master_Orders!D2:D174, "2026-07-25", Master_Orders!J2:J174, "COD", Master_Orders!K2:K174, "Delivered") | I36: =COUNTIFS(Master_Orders!D2:D174, "2026-07-25", Master_Orders!J2:J174, "Partial COD", Master_Orders!K2:K174, "Delivered") | J36: =COUNTIFS(Master_Orders!D2:D174, "2026-07-25", Master_Orders!J2:J174, "Prepaid", Master_Orders!K2:K174, "Delivered") | K36: =COUNTIFS(Master_Orders!D2:D174, "2026-07-25", Master_Orders!J2:J174, "COD", Master_Orders!K2:K174, "RTO / Returned") | L36: =COUNTIFS(Master_Orders!D2:D174, "2026-07-25", Master_Orders!J2:J174, "Partial COD", Master_Orders!K2:K174, "RTO / Returned") | M36: =COUNTIFS(Master_Orders!D2:D174, "2026-07-25", Master_Orders!J2:J174, "Prepaid", Master_Orders!K2:K174, "RTO / Returned") | N36: =E36+F36+G36
A37: 2026-07-26 | B37: =COUNTIFS(Master_Orders!D2:D174, "2026-07-26", Master_Orders!J2:J174, "COD") | C37: =COUNTIFS(Master_Orders!D2:D174, "2026-07-26", Master_Orders!J2:J174, "Partial COD") | D37: =COUNTIFS(Master_Orders!D2:D174, "2026-07-26", Master_Orders!J2:J174, "Prepaid") | E37: =SUMIFS(Master_Orders!E2:E174, Master_Orders!D2:D174, "2026-07-26", Master_Orders!J2:J174, "COD") | F37: =SUMIFS(Master_Orders!E2:E174, Master_Orders!D2:D174, "2026-07-26", Master_Orders!J2:J174, "Partial COD") | G37: =SUMIFS(Master_Orders!E2:E174, Master_Orders!D2:D174, "2026-07-26", Master_Orders!J2:J174, "Prepaid") | H37: =COUNTIFS(Master_Orders!D2:D174, "2026-07-26", Master_Orders!J2:J174, "COD", Master_Orders!K2:K174, "Delivered") | I37: =COUNTIFS(Master_Orders!D2:D174, "2026-07-26", Master_Orders!J2:J174, "Partial COD", Master_Orders!K2:K174, "Delivered") | J37: =COUNTIFS(Master_Orders!D2:D174, "2026-07-26", Master_Orders!J2:J174, "Prepaid", Master_Orders!K2:K174, "Delivered") | K37: =COUNTIFS(Master_Orders!D2:D174, "2026-07-26", Master_Orders!J2:J174, "COD", Master_Orders!K2:K174, "RTO / Returned") | L37: =COUNTIFS(Master_Orders!D2:D174, "2026-07-26", Master_Orders!J2:J174, "Partial COD", Master_Orders!K2:K174, "RTO / Returned") | M37: =COUNTIFS(Master_Orders!D2:D174, "2026-07-26", Master_Orders!J2:J174, "Prepaid", Master_Orders!K2:K174, "RTO / Returned") | N37: =E37+F37+G37
A38: 2026-07-27 | B38: =COUNTIFS(Master_Orders!D2:D174, "2026-07-27", Master_Orders!J2:J174, "COD") | C38: =COUNTIFS(Master_Orders!D2:D174, "2026-07-27", Master_Orders!J2:J174, "Partial COD") | D38: =COUNTIFS(Master_Orders!D2:D174, "2026-07-27", Master_Orders!J2:J174, "Prepaid") | E38: =SUMIFS(Master_Orders!E2:E174, Master_Orders!D2:D174, "2026-07-27", Master_Orders!J2:J174, "COD") | F38: =SUMIFS(Master_Orders!E2:E174, Master_Orders!D2:D174, "2026-07-27", Master_Orders!J2:J174, "Partial COD") | G38: =SUMIFS(Master_Orders!E2:E174, Master_Orders!D2:D174, "2026-07-27", Master_Orders!J2:J174, "Prepaid") | H38: =COUNTIFS(Master_Orders!D2:D174, "2026-07-27", Master_Orders!J2:J174, "COD", Master_Orders!K2:K174, "Delivered") | I38: =COUNTIFS(Master_Orders!D2:D174, "2026-07-27", Master_Orders!J2:J174, "Partial COD", Master_Orders!K2:K174, "Delivered") | J38: =COUNTIFS(Master_Orders!D2:D174, "2026-07-27", Master_Orders!J2:J174, "Prepaid", Master_Orders!K2:K174, "Delivered") | K38: =COUNTIFS(Master_Orders!D2:D174, "2026-07-27", Master_Orders!J2:J174, "COD", Master_Orders!K2:K174, "RTO / Returned") | L38: =COUNTIFS(Master_Orders!D2:D174, "2026-07-27", Master_Orders!J2:J174, "Partial COD", Master_Orders!K2:K174, "RTO / Returned") | M38: =COUNTIFS(Master_Orders!D2:D174, "2026-07-27", Master_Orders!J2:J174, "Prepaid", Master_Orders!K2:K174, "RTO / Returned") | N38: =E38+F38+G38
A39: 2026-07-28 | B39: =COUNTIFS(Master_Orders!D2:D174, "2026-07-28", Master_Orders!J2:J174, "COD") | C39: =COUNTIFS(Master_Orders!D2:D174, "2026-07-28", Master_Orders!J2:J174, "Partial COD") | D39: =COUNTIFS(Master_Orders!D2:D174, "2026-07-28", Master_Orders!J2:J174, "Prepaid") | E39: =SUMIFS(Master_Orders!E2:E174, Master_Orders!D2:D174, "2026-07-28", Master_Orders!J2:J174, "COD") | F39: =SUMIFS(Master_Orders!E2:E174, Master_Orders!D2:D174, "2026-07-28", Master_Orders!J2:J174, "Partial COD") | G39: =SUMIFS(Master_Orders!E2:E174, Master_Orders!D2:D174, "2026-07-28", Master_Orders!J2:J174, "Prepaid") | H39: =COUNTIFS(Master_Orders!D2:D174, "2026-07-28", Master_Orders!J2:J174, "COD", Master_Orders!K2:K174, "Delivered") | I39: =COUNTIFS(Master_Orders!D2:D174, "2026-07-28", Master_Orders!J2:J174, "Partial COD", Master_Orders!K2:K174, "Delivered") | J39: =COUNTIFS(Master_Orders!D2:D174, "2026-07-28", Master_Orders!J2:J174, "Prepaid", Master_Orders!K2:K174, "Delivered") | K39: =COUNTIFS(Master_Orders!D2:D174, "2026-07-28", Master_Orders!J2:J174, "COD", Master_Orders!K2:K174, "RTO / Returned") | L39: =COUNTIFS(Master_Orders!D2:D174, "2026-07-28", Master_Orders!J2:J174, "Partial COD", Master_Orders!K2:K174, "RTO / Returned") | M39: =COUNTIFS(Master_Orders!D2:D174, "2026-07-28", Master_Orders!J2:J174, "Prepaid", Master_Orders!K2:K174, "RTO / Returned") | N39: =E39+F39+G39
A40: 2026-07-29 | B40: =COUNTIFS(Master_Orders!D2:D174, "2026-07-29", Master_Orders!J2:J174, "COD") | C40: =COUNTIFS(Master_Orders!D2:D174, "2026-07-29", Master_Orders!J2:J174, "Partial COD") | D40: =COUNTIFS(Master_Orders!D2:D174, "2026-07-29", Master_Orders!J2:J174, "Prepaid") | E40: =SUMIFS(Master_Orders!E2:E174, Master_Orders!D2:D174, "2026-07-29", Master_Orders!J2:J174, "COD") | F40: =SUMIFS(Master_Orders!E2:E174, Master_Orders!D2:D174, "2026-07-29", Master_Orders!J2:J174, "Partial COD") | G40: =SUMIFS(Master_Orders!E2:E174, Master_Orders!D2:D174, "2026-07-29", Master_Orders!J2:J174, "Prepaid") | H40: =COUNTIFS(Master_Orders!D2:D174, "2026-07-29", Master_Orders!J2:J174, "COD", Master_Orders!K2:K174, "Delivered") | I40: =COUNTIFS(Master_Orders!D2:D174, "2026-07-29", Master_Orders!J2:J174, "Partial COD", Master_Orders!K2:K174, "Delivered") | J40: =COUNTIFS(Master_Orders!D2:D174, "2026-07-29", Master_Orders!J2:J174, "Prepaid", Master_Orders!K2:K174, "Delivered") | K40: =COUNTIFS(Master_Orders!D2:D174, "2026-07-29", Master_Orders!J2:J174, "COD", Master_Orders!K2:K174, "RTO / Returned") | L40: =COUNTIFS(Master_Orders!D2:D174, "2026-07-29", Master_Orders!J2:J174, "Partial COD", Master_Orders!K2:K174, "RTO / Returned") | M40: =COUNTIFS(Master_Orders!D2:D174, "2026-07-29", Master_Orders!J2:J174, "Prepaid", Master_Orders!K2:K174, "RTO / Returned") | N40: =E40+F40+G40
A41: 2026-07-30 | B41: =COUNTIFS(Master_Orders!D2:D174, "2026-07-30", Master_Orders!J2:J174, "COD") | C41: =COUNTIFS(Master_Orders!D2:D174, "2026-07-30", Master_Orders!J2:J174, "Partial COD") | D41: =COUNTIFS(Master_Orders!D2:D174, "2026-07-30", Master_Orders!J2:J174, "Prepaid") | E41: =SUMIFS(Master_Orders!E2:E174, Master_Orders!D2:D174, "2026-07-30", Master_Orders!J2:J174, "COD") | F41: =SUMIFS(Master_Orders!E2:E174, Master_Orders!D2:D174, "2026-07-30", Master_Orders!J2:J174, "Partial COD") | G41: =SUMIFS(Master_Orders!E2:E174, Master_Orders!D2:D174, "2026-07-30", Master_Orders!J2:J174, "Prepaid") | H41: =COUNTIFS(Master_Orders!D2:D174, "2026-07-30", Master_Orders!J2:J174, "COD", Master_Orders!K2:K174, "Delivered") | I41: =COUNTIFS(Master_Orders!D2:D174, "2026-07-30", Master_Orders!J2:J174, "Partial COD", Master_Orders!K2:K174, "Delivered") | J41: =COUNTIFS(Master_Orders!D2:D174, "2026-07-30", Master_Orders!J2:J174, "Prepaid", Master_Orders!K2:K174, "Delivered") | K41: =COUNTIFS(Master_Orders!D2:D174, "2026-07-30", Master_Orders!J2:J174, "COD", Master_Orders!K2:K174, "RTO / Returned") | L41: =COUNTIFS(Master_Orders!D2:D174, "2026-07-30", Master_Orders!J2:J174, "Partial COD", Master_Orders!K2:K174, "RTO / Returned") | M41: =COUNTIFS(Master_Orders!D2:D174, "2026-07-30", Master_Orders!J2:J174, "Prepaid", Master_Orders!K2:K174, "RTO / Returned") | N41: =E41+F41+G41
...

Sheet COD_Day_Wise
A1: JANVI AIKA - INDIVIDUAL DAYWISE REPORT: CASH ON DELIVERY (COD)
A3: Order Date | B3: COD Orders | C3: COD Revenue (Rs.) | D3: AOV (Rs.) | E3: Delivered Count | F3: Delivered Rev (Rs.) | G3: RTO Count | H3: RTO Rev Loss (Rs.) | I3: Canceled Count | J3: In Transit Count | K3: Realization Rate %
A4: 2026-06-24 | B4: =COUNTIFS(Master_Orders!D2:D174, "2026-06-24", Master_Orders!J2:J174, "COD") | C4: =SUMIFS(Master_Orders!E2:E174, Master_Orders!D2:D174, "2026-06-24", Master_Orders!J2:J174, "COD") | D4: =C4/B4 | E4: =COUNTIFS(Master_Orders!D2:D174, "2026-06-24", Master_Orders!J2:J174, "COD", Master_Orders!K2:K174, "Delivered") | F4: =SUMIFS(Master_Orders!E2:E174, Master_Orders!D2:D174, "2026-06-24", Master_Orders!J2:J174, "COD", Master_Orders!K2:K174, "Delivered") | G4: =COUNTIFS(Master_Orders!D2:D174, "2026-06-24", Master_Orders!J2:J174, "COD", Master_Orders!K2:K174, "RTO / Returned") | H4: =SUMIFS(Master_Orders!E2:E174, Master_Orders!D2:D174, "2026-06-24", Master_Orders!J2:J174, "COD", Master_Orders!K2:K174, "RTO / Returned") | I4: =COUNTIFS(Master_Orders!D2:D174, "2026-06-24", Master_Orders!J2:J174, "COD", Master_Orders!K2:K174, "Canceled") | J4: =COUNTIFS(Master_Orders!D2:D174, "2026-06-24", Master_Orders!J2:J174, "COD", Master_Orders!K2:K174, "In Transit") | K4: =E4/B4
A5: 2026-06-25 | B5: =COUNTIFS(Master_Orders!D2:D174, "2026-06-25", Master_Orders!J2:J174, "COD") | C5: =SUMIFS(Master_Orders!E2:E174, Master_Orders!D2:D174, "2026-06-25", Master_Orders!J2:J174, "COD") | D5: =C5/B5 | E5: =COUNTIFS(Master_Orders!D2:D174, "2026-06-25", Master_Orders!J2:J174, "COD", Master_Orders!K2:K174, "Delivered") | F5: =SUMIFS(Master_Orders!E2:E174, Master_Orders!D2:D174, "2026-06-25", Master_Orders!J2:J174, "COD", Master_Orders!K2:K174, "Delivered") | G5: =COUNTIFS(Master_Orders!D2:D174, "2026-06-25", Master_Orders!J2:J174, "COD", Master_Orders!K2:K174, "RTO / Returned") | H5: =SUMIFS(Master_Orders!E2:E174, Master_Orders!D2:D174, "2026-06-25", Master_Orders!J2:J174, "COD", Master_Orders!K2:K174, "RTO / Returned") | I5: =COUNTIFS(Master_Orders!D2:D174, "2026-06-25", Master_Orders!J2:J174, "COD", Master_Orders!K2:K174, "Canceled") | J5: =COUNTIFS(Master_Orders!D2:D174, "2026-06-25", Master_Orders!J2:J174, "COD", Master_Orders!K2:K174, "In Transit") | K5: =E5/B5
